Workbook

Sheet تعليمات
A1: قالب تهجير بيانات الزبائن - V3 | B1: قالب تهجير بيانات الزبائن - V3 | C1: قالب تهجير بيانات الزبائن - V3 | D1: قالب تهجير بيانات الزبائن - V3 | E1: قالب تهجير بيانات الزبائن - V3 | F1: قالب تهجير بيانات الزبائن - V3 | G1: قالب تهجير بيانات الزبائن - V3 | H1: قالب تهجير بيانات الزبائن - V3
A2: نسخة منظمة: الزبون في صف واحد، وكل أرقام التواصل والوسطاء في شيتات مستقلة. الترتيب 1 هو الأساسي. | B2: نسخة منظمة: الزبون في صف واحد، وكل أرقام التواصل والوسطاء في شيتات مستقلة. الترتيب 1 هو الأساسي. | C2: نسخة منظمة: الزبون في صف واحد، وكل أرقام التواصل والوسطاء في شيتات مستقلة. الترتيب 1 هو الأساسي. | D2: نسخة منظمة: الزبون في صف واحد، وكل أرقام التواصل والوسطاء في شيتات مستقلة. الترتيب 1 هو الأساسي. | E2: نسخة منظمة: الزبون في صف واحد، وكل أرقام التواصل والوسطاء في شيتات مستقلة. الترتيب 1 هو الأساسي. | F2: نسخة منظمة: الزبون في صف واحد، وكل أرقام التواصل والوسطاء في شيتات مستقلة. الترتيب 1 هو الأساسي. | G2: نسخة منظمة: الزبون في صف واحد، وكل أرقام التواصل والوسطاء في شيتات مستقلة. الترتيب 1 هو الأساسي. | H2: نسخة منظمة: الزبون في صف واحد، وكل أرقام التواصل والوسطاء في شيتات مستقلة. الترتيب 1 هو الأساسي.
A4: الخطوة | B4: ما الذي يجب فعله | C4: لماذا مهم؟ | E4: قرارات الصف
A5: 1 | B5: املأ شيت الزبائن بصف واحد لكل زبون، بدون تكرار الرقم الأساسي أو الوسيط الأساسي داخله. | C5: حتى تبقى بيانات الهوية والعنوان منفصلة عن البيانات المتعددة. | E5: READY | F5: جاهز للاستيراد كزبون أو اسم مقترح حسب الشيت.
A6: 2 | B6: املأ شيت أرقام التواصل لكل أرقام الزبائن والأسماء المقترحة. استخدم entity_type و entity_key للربط. | C6: نفس الزبون يمكن أن يملك أكثر من رقم بدون أعمدة إضافية. | E6: TO_PROPOSED | F6: صف زبون سينتقل إلى شيت أسماء مقترحة.
A7: 3 | B7: ضع contact_order=1 لأول رقم. هذا الرقم يعتبر الأساسي حتى لو تركت is_primary فارغة. | C7: يلبي قاعدة أن القيمة الأولى هي الأساسية. | E7: REVIEW | F7: ناقص أو فيه تعارض يحتاج تنظيف.
A8: 4 | B8: املأ شيت الوسطاء بنفس الفكرة: referrer_order=1 هو الوسيط الأساسي. | C8: لا حاجة لتكرار الوسيط في شيت الزبائن وشيت آخر. | E8: SKIP | F8: مستبعد بإرادة الفريق.
A9: 5 | B9: العنوان صار أربع مستويات: محافظة، منطقة، ناحية، حي. final_geo_unit_id محسوب من أعمق ID متوفر. | C9: النظام الجغرافي لديه مستوى مستقل للحي، ويجب الحفاظ عليه في الهجرة. | E9: قاعدة الأرقام | F9: أول رقم لكل entity_key هو الأساسي: contact_order=1.
A10: 6 | B10: أي زبون غير مؤكد أو مكرر أو ناقص أو عنوانه غير واضح اجعل final_destination=proposed_name وضع proposed_name_key. | C10: يبقى السجل محفوظا كاسم مقترح بدل إدخاله كزبون ناقص. | E10: قاعدة الوسطاء | F10: أول وسيط لكل entity_key هو الأساسي: referrer_order=1.
A11: 7 | B11: في شيت أسماء مقترحة لا تدخل الرقم داخل الصف. ضع أرقامه في شيت أرقام التواصل مع entity_type=proposed_name. | C11: نفس نموذج الفصل والاختصار. | E11: تاريخ القالب | F11: 2026-07-05
A12: 8 | B12: راجع row_status و row_issues. استورد فقط READY أو TO_PROPOSED حسب المسار. | C12: يقلل أخطاء الاستيراد قبل لمس قاعدة البيانات. | E12: نطاق الصفوف | F12: 6-505

Sheet الزبائن
A1: الزبائن - قالب التنظيف والاستيراد V3 | B1: الزبائن - قالب التنظيف والاستيراد V3 | C1: الزبائن - قالب التنظيف والاستيراد V3 | D1: الزبائن - قالب التنظيف والاستيراد V3 | E1: الزبائن - قالب التنظيف والاستيراد V3 | F1: الزبائن - قالب التنظيف والاستيراد V3 | G1: الزبائن - قالب التنظيف والاستيراد V3 | H1: الزبائن - قالب التنظيف والاستيراد V3 | I1: الزبائن - قالب التنظيف والاستيراد V3 | J1: الزبائن - قالب التنظيف والاستيراد V3 | K1: الزبائن - قالب التنظيف والاستيراد V3 | L1: الزبائن - قالب التنظيف والاستيراد V3 | M1: الزبائن - قالب التنظيف والاستيراد V3 | N1: الزبائن - قالب التنظيف والاستيراد V3 | O1: الزبائن - قالب التنظيف والاستيراد V3 | P1: الزبائن - قالب التنظيف والاستيراد V3 | Q1: الزبائن - قالب التنظيف والاستيراد V3 | R1: الزبائن - قالب التنظيف والاستيراد V3 | S1: الزبائن - قالب التنظيف والاستيراد V3 | U1: الزبائن - قالب التنظيف والاستيراد V3 | V1: الزبائن - قالب التنظيف والاستيراد V3 | W1: الزبائن - قالب التنظيف والاستيراد V3 | X1: الزبائن - قالب التنظيف والاستيراد V3 | Y1: الزبائن - قالب التنظيف والاستيراد V3 | Z1: الزبائن - قالب التنظيف والاستيراد V3 | AA1: الزبائن - قالب التنظيف والاستيراد V3 | AB1: الزبائن - قالب التنظيف والاستيراد V3 | AC1: الزبائن - قالب التنظيف والاستيراد V3 | AD1: الزبائن - قالب التنظيف والاستيراد V3 | AE1: الزبائن - قالب التنظيف والاستيراد V3 | AF1: الزبائن - قالب التنظيف والاستيراد V3 | AG1: الزبائن - قالب التنظيف والاستيراد V3 | AH1: الزبائن - قالب التنظيف والاستيراد V3 | AI1: الزبائن - قالب التنظيف والاستيراد V3 | AJ1: الزبائن - قالب التنظيف والاستيراد V3 | AK1: الزبائن - قالب التنظيف والاستيراد V3 | AL1: الزبائن - قالب التنظيف والاستيراد V3 | AM1: الزبائن - قالب التنظيف والاستيراد V3 | AN1: الزبائن - قالب التنظيف والاستيراد V3 | AO1: الزبائن - قالب التنظيف والاستيراد V3 | AP1: الزبائن - قالب التنظيف والاستيراد V3 | AQ1: الزبائن - قالب التنظيف والاستيراد V3 | AR1: الزبائن - قالب التنظيف والاستيراد V3 | AS1: الزبائن - قالب التنظيف والاستيراد V3 | AT1: الزبائن - قالب التنظيف والاستيراد V3 | AU1: الزبائن - قالب التنظيف والاستيراد V3 | AV1: الزبائن - قالب التنظيف والاستيراد V3 | AW1: الزبائن - قالب التنظيف والاستيراد V3 | AX1: الزبائن - قالب التنظيف والاستيراد V3 | AY1: الزبائن - قالب التنظيف والاستيراد V3 | AZ1: الزبائن - قالب التنظيف والاستيراد V3 | BA1: الزبائن - قالب التنظيف والاستيراد V3
A2: صف واحد لكل زبون. أرقام التواصل والوسطاء في شيتات مستقلة، و final_geo_unit_id يحسب أعمق مستوى جغرافي متوفر. | B2: صف واحد لكل زبون. أرقام التواصل والوسطاء في شيتات مستقلة، و final_geo_unit_id يحسب أعمق مستوى جغرافي متوفر. | C2: صف واحد لكل زبون. أرقام التواصل والوسطاء في شيتات مستقلة، و final_geo_unit_id يحسب أعمق مستوى جغرافي متوفر. | D2: صف واحد لكل زبون. أرقام التواصل والوسطاء في شيتات مستقلة، و final_geo_unit_id يحسب أعمق مستوى جغرافي متوفر. | E2: صف واحد لكل زبون. أرقام التواصل والوسطاء في شيتات مستقلة، و final_geo_unit_id يحسب أعمق مستوى جغرافي متوفر. | F2: صف واحد لكل زبون. أرقام التواصل والوسطاء في شيتات مستقلة، و final_geo_unit_id يحسب أعمق مستوى جغرافي متوفر. | G2: صف واحد لكل زبون. أرقام التواصل والوسطاء في شيتات مستقلة، و final_geo_unit_id يحسب أعمق مستوى جغرافي متوفر. | H2: صف واحد لكل زبون. أرقام التواصل والوسطاء في شيتات مستقلة، و final_geo_unit_id يحسب أعمق مستوى جغرافي متوفر. | I2: صف واحد لكل زبون. أرقام التواصل والوسطاء في شيتات مستقلة، و final_geo_unit_id يحسب أعمق مستوى جغرافي متوفر. | J2: صف واحد لكل زبون. أرقام التواصل والوسطاء في شيتات مستقلة، و final_geo_unit_id يحسب أعمق مستوى جغرافي متوفر. | K2: صف واحد لكل زبون. أرقام التواصل والوسطاء في شيتات مستقلة، و final_geo_unit_id يحسب أعمق مستوى جغرافي متوفر. | L2: صف واحد لكل زبون. أرقام التواصل والوسطاء في شيتات مستقلة، و final_geo_unit_id يحسب أعمق مستوى جغرافي متوفر. | M2: صف واحد لكل زبون. أرقام التواصل والوسطاء في شيتات مستقلة، و final_geo_unit_id يحسب أعمق مستوى جغرافي متوفر. | N2: صف واحد لكل زبون. أرقام التواصل والوسطاء في شيتات مستقلة، و final_geo_unit_id يحسب أعمق مستوى جغرافي متوفر. | O2: صف واحد لكل زبون. أرقام التواصل والوسطاء في شيتات مستقلة، و final_geo_unit_id يحسب أعمق مستوى جغرافي متوفر. | P2: صف واحد لكل زبون. أرقام التواصل والوسطاء في شيتات مستقلة، و final_geo_unit_id يحسب أعمق مستوى جغرافي متوفر. | Q2: صف واحد لكل زبون. أرقام التواصل والوسطاء في شيتات مستقلة، و final_geo_unit_id يحسب أعمق مستوى جغرافي متوفر. | R2: صف واحد لكل زبون. أرقام التواصل والوسطاء في شيتات مستقلة، و final_geo_unit_id يحسب أعمق مستوى جغرافي متوفر. | S2: صف واحد لكل زبون. أرقام التواصل والوسطاء في شيتات مستقلة، و final_geo_unit_id يحسب أعمق مستوى جغرافي متوفر. | U2: صف واحد لكل زبون. أرقام التواصل والوسطاء في شيتات مستقلة، و final_geo_unit_id يحسب أعمق مستوى جغرافي متوفر. | V2: صف واحد لكل زبون. أرقام التواصل والوسطاء في شيتات مستقلة، و final_geo_unit_id يحسب أعمق مستوى جغرافي متوفر. | W2: صف واحد لكل زبون. أرقام التواصل والوسطاء في شيتات مستقلة، و final_geo_unit_id يحسب أعمق مستوى جغرافي متوفر. | X2: صف واحد لكل زبون. أرقام التواصل والوسطاء في شيتات مستقلة، و final_geo_unit_id يحسب أعمق مستوى جغرافي متوفر. | Y2: صف واحد لكل زبون. أرقام التواصل والوسطاء في شيتات مستقلة، و final_geo_unit_id يحسب أعمق مستوى جغرافي متوفر. | Z2: صف واحد لكل زبون. أرقام التواصل والوسطاء في شيتات مستقلة، و final_geo_unit_id يحسب أعمق مستوى جغرافي متوفر. | AA2: صف واحد لكل زبون. أرقام التواصل والوسطاء في شيتات مستقلة، و final_geo_unit_id يحسب أعمق مستوى جغرافي متوفر. | AB2: صف واحد لكل زبون. أرقام التواصل والوسطاء في شيتات مستقلة، و final_geo_unit_id يحسب أعمق مستوى جغرافي متوفر. | AC2: صف واحد لكل زبون. أرقام التواصل والوسطاء في شيتات مستقلة، و final_geo_unit_id يحسب أعمق مستوى جغرافي متوفر. | AD2: صف واحد لكل زبون. أرقام التواصل والوسطاء في شيتات مستقلة، و final_geo_unit_id يحسب أعمق مستوى جغرافي متوفر. | AE2: صف واحد لكل زبون. أرقام التواصل والوسطاء في شيتات مستقلة، و final_geo_unit_id يحسب أعمق مستوى جغرافي متوفر. | AF2: صف واحد لكل زبون. أرقام التواصل والوسطاء في شيتات مستقلة، و final_geo_unit_id يحسب أعمق مستوى جغرافي متوفر. | AG2: صف واحد لكل زبون. أرقام التواصل والوسطاء في شيتات مستقلة، و final_geo_unit_id يحسب أعمق مستوى جغرافي متوفر. | AH2: صف واحد لكل زبون. أرقام التواصل والوسطاء في شيتات مستقلة، و final_geo_unit_id يحسب أعمق مستوى جغرافي متوفر. | AI2: صف واحد لكل زبون. أرقام التواصل والوسطاء في شيتات مستقلة، و final_geo_unit_id يحسب أعمق مستوى جغرافي متوفر. | AJ2: صف واحد لكل زبون. أرقام التواصل والوسطاء في شيتات مستقلة، و final_geo_unit_id يحسب أعمق مستوى جغرافي متوفر. | AK2: صف واحد لكل زبون. أرقام التواصل والوسطاء في شيتات مستقلة، و final_geo_unit_id يحسب أعمق مستوى جغرافي متوفر. | AL2: صف واحد لكل زبون. أرقام التواصل والوسطاء في شيتات مستقلة، و final_geo_unit_id يحسب أعمق مستوى جغرافي متوفر. | AM2: صف واحد لكل زبون. أرقام التواصل والوسطاء في شيتات مستقلة، و final_geo_unit_id يحسب أعمق مستوى جغرافي متوفر. | AN2: صف واحد لكل زبون. أرقام التواصل والوسطاء في شيتات مستقلة، و final_geo_unit_id يحسب أعمق مستوى جغرافي متوفر. | AO2: صف واحد لكل زبون. أرقام التواصل والوسطاء في شيتات مستقلة، و final_geo_unit_id يحسب أعمق مستوى جغرافي متوفر. | AP2: صف واحد لكل زبون. أرقام التواصل والوسطاء في شيتات مستقلة، و final_geo_unit_id يحسب أعمق مستوى جغرافي متوفر. | AQ2: صف واحد لكل زبون. أرقام التواصل والوسطاء في شيتات مستقلة، و final_geo_unit_id يحسب أعمق مستوى جغرافي متوفر. | AR2: صف واحد لكل زبون. أرقام التواصل والوسطاء في شيتات مستقلة، و final_geo_unit_id يحسب أعمق مستوى جغرافي متوفر. | AS2: صف واحد لكل زبون. أرقام التواصل والوسطاء في شيتات مستقلة، و final_geo_unit_id يحسب أعمق مستوى جغرافي متوفر. | AT2: صف واحد لكل زبون. أرقام التواصل والوسطاء في شيتات مستقلة، و final_geo_unit_id يحسب أعمق مستوى جغرافي متوفر. | AU2: صف واحد لكل زبون. أرقام التواصل والوسطاء في شيتات مستقلة، و final_geo_unit_id يحسب أعمق مستوى جغرافي متوفر. | AV2: صف واحد لكل زبون. أرقام التواصل والوسطاء في شيتات مستقلة، و final_geo_unit_id يحسب أعمق مستوى جغرافي متوفر. | AW2: صف واحد لكل زبون. أرقام التواصل والوسطاء في شيتات مستقلة، و final_geo_unit_id يحسب أعمق مستوى جغرافي متوفر. | AX2: صف واحد لكل زبون. أرقام التواصل والوسطاء في شيتات مستقلة، و final_geo_unit_id يحسب أعمق مستوى جغرافي متوفر. | AY2: صف واحد لكل زبون. أرقام التواصل والوسطاء في شيتات مستقلة، و final_geo_unit_id يحسب أعمق مستوى جغرافي متوفر. | AZ2: صف واحد لكل زبون. أرقام التواصل والوسطاء في شيتات مستقلة، و final_geo_unit_id يحسب أعمق مستوى جغرافي متوفر. | BA2: صف واحد لكل زبون. أرقام التواصل والوسطاء في شيتات مستقلة، و final_geo_unit_id يحسب أعمق مستوى جغرافي متوفر.
A3: migration_customer_key | B3: import_action | C3: old_system_customer_id | D3: old_source_note | E3: branch_id | F3: branch_name | G3: first_name | H3: father_name | I3: last_name | J3: nickname | K3: full_name_preview | L3: governorate_id | M3: governorate_name | N3: region_id | O3: region_name | P3: sub_area_id | Q3: sub_area_name | R3: neighborhood_id | S3: neighborhood_name | V3: detailed_address | W3: gps_lat | X3: gps_lng | Y3: assignment_user_ids | Z3: is_candidate | AA3: candidate_status | AB3: target_client | AC3: gender | AD3: birth_date | AE3: mother_name | AF3: national_id | AG3: national_id_registry | AH3: national_id_issued_by | AI3: national_id_issue_date | AJ3: national_id_box | AK3: occupation | AL3: spouse_occupation | AM3: water_source | AN3: data_quality | AO3: rating | AP3: do_not_contact | AQ3: cooldown_until | AR3: cooldown_reason | AS3: notes | AT3: cleanup_status | AU3: cleanup_notes | AV3: final_destination | AW3: proposed_move_reason | AX3: proposed_name_key | AY3: triage_decision_notes | AZ3: row_status | BA3: row_issues
A4: ربط الهجرة | B4: ربط الهجرة | C4: ربط الهجرة | D4: ربط الهجرة | E4: الفرع والملكية | F4: الفرع والملكية | G4: هوية الزبون | H4: هوية الزبون | I4: هوية الزبون | J4: هوية الزبون | K4: هوية الزبون | L4: العنوان - 4 مستويات | M4: العنوان - 4 مستويات | N4: العنوان - 4 مستويات | O4: العنوان - 4 مستويات | P4: العنوان - 4 مستويات | Q4: العنوان - 4 مستويات | R4: العنوان - 4 مستويات | S4: العنوان - 4 مستويات | U4: العنوان - 4 مستويات | V4: العنوان | W4: العنوان | X4: العنوان | Y4: الفرع والملكية | Z4: حالة الزبون | AA4: حالة الزبون | AB4: حالة الزبون | AC4: بيانات مدنية | AD4: بيانات مدنية | AE4: بيانات مدنية | AF4: بيانات مدنية | AG4: بيانات مدنية | AH4: بيانات مدنية | AI4: بيانات مدنية | AJ4: بيانات مدنية | AK4: بيانات إضافية | AL4: بيانات إضافية | AM4: بيانات إضافية | AN4: ضبط وتنظيف | AO4: ضبط وتنظيف | AP4: ضبط وتنظيف | AQ4: ضبط وتنظيف | AR4: ضبط وتنظيف | AS4: مراجعة | AT4: مراجعة | AU4: مراجعة | AV4: قرار الفرز | AW4: قرار الفرز | AX4: قرار الفرز | AY4: قرار الفرز | AZ4: مراجعة | BA4: مراجعة
A5: مفتاح الزبون للهجرة | B5: إجراء الاستيراد | C5: ID النظام القديم | D5: مصدر/جدول قديم | E5: ID الفرع | F5: اسم الفرع للمراجعة | G5: الاسم الأول | H5: اسم الأب | I5: الكنية/العائلة | J5: اللقب | K5: الاسم الكامل - تلقائي | L5: ID المحافظة | M5: اسم المحافظة | N5: ID المنطقة | O5: اسم المنطقة | P5: ID الناحية | Q5: اسم الناحية | R5: ID الحي | S5: اسم الحي | T5: العنوان القديم | U5: معلومات عن الموقع / قديم | V5: العنوان التفصيلي | W5: GPS خط العرض | X5: GPS خط الطول | Y5: IDs المستخدمين المسندين | Z5: هل هو مرشح؟ | AA5: حالة المرشح داخل الزبون | AB5: زبون مستهدف | AC5: الجنس | AD5: تاريخ الميلاد | AE5: اسم الأم | AF5: الرقم الوطني | AG5: القيد/السجل | AH5: جهة الإصدار | AI5: تاريخ الإصدار | AJ5: الخانة | AK5: المهنة | AL5: مهنة الزوج/الزوجة | AM5: مصدر المياه | AN5: جودة البيانات | AO5: التقييم | AP5: عدم التواصل | AQ5: إيقاف التواصل حتى | AR5: سبب إيقاف التواصل | AS5: ملاحظات | AT5: حالة التنظيف | AU5: ملاحظات التنظيف | AV5: الوجهة النهائية | AW5: سبب النقل لاسم مقترح | AX5: مفتاح الاسم المقترح | AY5: ملاحظات قرار الفرز | AZ5: حالة الصف - تلقائي | BA5: مشاكل الصف - تلقائي
A6: CUST-0001 | B6: create | C6: old-1388 | D6: legacy_customers | E6: 1 | F6: دمشق | G6: أحمد | H6: خالد | I6: زيتون | J6: أبو أيوب | K6: =IF(TRIM(G6&" "&H6&" "&I6&IF(J6<>""," ("&J6&")",""))="","",TRIM(G6&" "&H6&" "&I6&IF(J6<>""," ("&J6&")",""))) -> أحمد خالد زيتون (أبو أيوب) | L6: 10 | M6: دمشق | N6: 24 | O6: دمشق | P6: 88 | Q6: المزة | R6: 125 | S6: المزة الشرقية | V6: المزة - جانب الحديقة - بناء 12 | W6: 33.5102 | X6: 36.2784 | Y6: 12,18 | Z6: FALSE | AC6: male | AD6: 31179 | AE6: فاطمة | AF6: 01234567890 | AK6: موظف | AM6: شبكة | AN6: correct | AO6: Undefined | AP6: FALSE | AS6: صف مثال - احذفه قبل الاستيراد | AT6: cleaned | AU6: جاهز بعد مطابقة IDs | AV6: client | AY6: جاهز كزبون | AZ6: =IF(AND(A6="",B6="",E6="",G6="",I6="",AV6="",AX6=""),"",IF(OR(B6="skip",AV6="skip"),"SKIP",IF(OR(B6="to_candidate",AV6="proposed_name"),IF(OR(A6="",AW6="",AX6="",COUNTIF($A$6:$A$505,A6)>1),"REVIEW","TO_PROPOSED"),IF(OR(B6="",A6="",E6="",G6="",I6="",U6="",AV6="",COUNTIF($A$6:$A$505,A6)>1,(COUNTIFS('أرقام التواصل'!$A$6:$A$505,"client",'أرقام التواصل'!$B$6:$B$505,A6,'أرقام التواصل'!$I$6:$I$505,"TRUE")+COUNTIFS('أرقام التواصل'!$A$6:$A$505,"client",'أرقام التواصل'!$B$6:$B$505,A6,'أرقام التواصل'!$C$6:$C$505,1))=0),"REVIEW","READY")))) -> REVIEW | BA6: =IF(AZ6="","",IF(OR(AZ6="READY",AZ6="TO_PROPOSED"),"",IF(AZ6="SKIP","Skipped by decision",TRIM(IF(B6="","missing import_action; ","")&IF(A6="","missing migration_customer_key; ","")&IF(AND(A6<>"",COUNTIF($A$6:$A$505,A6)>1),"duplicate migration_customer_key; ","")&IF(AND(NOT(OR(B6="to_candidate",AV6="proposed_name")),E6=""),"missing branch_id; ","")&IF(AND(NOT(OR(B6="to_candidate",AV6="proposed_name")),G6=""),"missing first_name; ","")&IF(AND(NOT(OR(B6="to_candidate",AV6="proposed_name")),I6=""),"missing last_name; ","")&IF(AND(NOT(OR(B6="to_candidate",AV6="proposed_name")),U6=""),"missing final_geo_unit_id; ","")&IF(AV6="","missing final_destination; ","")&IF(AND(NOT(OR(B6="to_candidate",AV6="proposed_name")),(COUNTIFS('أرقام التواصل'!$A$6:$A$505,"client",'أرقام التواصل'!$B$6:$B$505,A6,'أرقام التواصل'!$I$6:$I$505,"TRUE")+COUNTIFS('أرقام التواصل'!$A$6:$A$505,"client",'أرقام التواصل'!$B$6:$B$505,A6,'أرقام التواصل'!$C$6:$C$505,1))=0),"missing primary contact in أرقام التواصل; ","")&IF(OR(B6="to_candidate",AV6="proposed_name"),IF(AW6="","missing proposed_move_reason; ","")&IF(AX6="","missing proposed_name_key; ",""),""))))) -> missing final_geo_unit_id;
A7: CUST-0002 | B7: to_candidate | C7: old-1401 | D7: legacy_excel | E7: 2 | F7: حلب | G7: سارة | I7: حسن | K7: =IF(TRIM(G7&" "&H7&" "&I7&IF(J7<>""," ("&J7&")",""))="","",TRIM(G7&" "&H7&" "&I7&IF(J7<>""," ("&J7&")",""))) -> سارة حسن | L7: 11 | M7: حلب | N7: 31 | O7: حلب | V7: قرب الدوار - العنوان بحاجة تحديد | Z7: FALSE | AC7: female | AN7: needs_edit | AO7: Undefined | AP7: FALSE | AS7: عنوان غير واضح ورقم بحاجة تأكيد | AT7: review_needed | AU7: ينقل لمسار الأسماء المقترحة | AV7: proposed_name | AW7: unclear_address | AX7: PN-CUST-0002 | AY7: يبقى كاسم مقترح حتى تثبيت العنوان | AZ7: =IF(AND(A7="",B7="",E7="",G7="",I7="",AV7="",AX7=""),"",IF(OR(B7="skip",AV7="skip"),"SKIP",IF(OR(B7="to_candidate",AV7="proposed_name"),IF(OR(A7="",AW7="",AX7="",COUNTIF($A$6:$A$505,A7)>1),"REVIEW","TO_PROPOSED"),IF(OR(B7="",A7="",E7="",G7="",I7="",U7="",AV7="",COUNTIF($A$6:$A$505,A7)>1,(COUNTIFS('أرقام التواصل'!$A$6:$A$505,"client",'أرقام التواصل'!$B$6:$B$505,A7,'أرقام التواصل'!$I$6:$I$505,"TRUE")+COUNTIFS('أرقام التواصل'!$A$6:$A$505,"client",'أرقام التواصل'!$B$6:$B$505,A7,'أرقام التواصل'!$C$6:$C$505,1))=0),"REVIEW","READY")))) -> TO_PROPOSED | BA7: =IF(AZ7="","",IF(OR(AZ7="READY",AZ7="TO_PROPOSED"),"",IF(AZ7="SKIP","Skipped by decision",TRIM(IF(B7="","missing import_action; ","")&IF(A7="","missing migration_customer_key; ","")&IF(AND(A7<>"",COUNTIF($A$6:$A$505,A7)>1),"duplicate migration_customer_key; ","")&IF(AND(NOT(OR(B7="to_candidate",AV7="proposed_name")),E7=""),"missing branch_id; ","")&IF(AND(NOT(OR(B7="to_candidate",AV7="proposed_name")),G7=""),"missing first_name; ","")&IF(AND(NOT(OR(B7="to_candidate",AV7="proposed_name")),I7=""),"missing last_name; ","")&IF(AND(NOT(OR(B7="to_candidate",AV7="proposed_name")),U7=""),"missing final_geo_unit_id; ","")&IF(AV7="","missing final_destination; ","")&IF(AND(NOT(OR(B7="to_candidate",AV7="proposed_name")),(COUNTIFS('أرقام التواصل'!$A$6:$A$505,"client",'أرقام التواصل'!$B$6:$B$505,A7,'أرقام التواصل'!$I$6:$I$505,"TRUE")+COUNTIFS('أرقام التواصل'!$A$6:$A$505,"client",'أرقام التواصل'!$B$6:$B$505,A7,'أرقام التواصل'!$C$6:$C$505,1))=0),"missing primary contact in أرقام التواصل; ","")&IF(OR(B7="to_candidate",AV7="proposed_name"),IF(AW7="","missing proposed_move_reason; ","")&IF(AX7="","missing proposed_name_key; ",""),"")))))
K8: =IF(TRIM(G8&" "&H8&" "&I8&IF(J8<>""," ("&J8&")",""))="","",TRIM(G8&" "&H8&" "&I8&IF(J8<>""," ("&J8&")",""))) | U8: =IF(AND(L8="",N8="",P8="",R8=""),"",IF(R8<>"",R8,IF(P8<>"",P8,IF(N8<>"",N8,L8)))) | AZ8: =IF(AND(A8="",B8="",E8="",G8="",I8="",AV8="",AX8=""),"",IF(OR(B8="skip",AV8="skip"),"SKIP",IF(OR(B8="to_candidate",AV8="proposed_name"),IF(OR(A8="",AW8="",AX8="",COUNTIF($A$6:$A$505,A8)>1),"REVIEW","TO_PROPOSED"),IF(OR(B8="",A8="",E8="",G8="",I8="",U8="",AV8="",COUNTIF($A$6:$A$505,A8)>1,(COUNTIFS('أرقام التواصل'!$A$6:$A$505,"client",'أرقام التواصل'!$B$6:$B$505,A8,'أرقام التواصل'!$I$6:$I$505,"TRUE")+COUNTIFS('أرقام التواصل'!$A$6:$A$505,"client",'أرقام التواصل'!$B$6:$B$505,A8,'أرقام التواصل'!$C$6:$C$505,1))=0),"REVIEW","READY")))) | BA8: =IF(AZ8="","",IF(OR(AZ8="READY",AZ8="TO_PROPOSED"),"",IF(AZ8="SKIP","Skipped by decision",TRIM(IF(B8="","missing import_action; ","")&IF(A8="","missing migration_customer_key; ","")&IF(AND(A8<>"",COUNTIF($A$6:$A$505,A8)>1),"duplicate migration_customer_key; ","")&IF(AND(NOT(OR(B8="to_candidate",AV8="proposed_name")),E8=""),"missing branch_id; ","")&IF(AND(NOT(OR(B8="to_candidate",AV8="proposed_name")),G8=""),"missing first_name; ","")&IF(AND(NOT(OR(B8="to_candidate",AV8="proposed_name")),I8=""),"missing last_name; ","")&IF(AND(NOT(OR(B8="to_candidate",AV8="proposed_name")),U8=""),"missing final_geo_unit_id; ","")&IF(AV8="","missing final_destination; ","")&IF(AND(NOT(OR(B8="to_candidate",AV8="proposed_name")),(COUNTIFS('أرقام التواصل'!$A$6:$A$505,"client",'أرقام التواصل'!$B$6:$B$505,A8,'أرقام التواصل'!$I$6:$I$505,"TRUE")+COUNTIFS('أرقام التواصل'!$A$6:$A$505,"client",'أرقام التواصل'!$B$6:$B$505,A8,'أرقام التواصل'!$C$6:$C$505,1))=0),"missing primary contact in أرقام التواصل; ","")&IF(OR(B8="to_candidate",AV8="proposed_name"),IF(AW8="","missing proposed_move_reason; ","")&IF(AX8="","missing proposed_name_key; ",""),"")))))
K9: =IF(TRIM(G9&" "&H9&" "&I9&IF(J9<>""," ("&J9&")",""))="","",TRIM(G9&" "&H9&" "&I9&IF(J9<>""," ("&J9&")",""))) | U9: =IF(AND(L9="",N9="",P9="",R9=""),"",IF(R9<>"",R9,IF(P9<>"",P9,IF(N9<>"",N9,L9)))) | AZ9: =IF(AND(A9="",B9="",E9="",G9="",I9="",AV9="",AX9=""),"",IF(OR(B9="skip",AV9="skip"),"SKIP",IF(OR(B9="to_candidate",AV9="proposed_name"),IF(OR(A9="",AW9="",AX9="",COUNTIF($A$6:$A$505,A9)>1),"REVIEW","TO_PROPOSED"),IF(OR(B9="",A9="",E9="",G9="",I9="",U9="",AV9="",COUNTIF($A$6:$A$505,A9)>1,(COUNTIFS('أرقام التواصل'!$A$6:$A$505,"client",'أرقام التواصل'!$B$6:$B$505,A9,'أرقام التواصل'!$I$6:$I$505,"TRUE")+COUNTIFS('أرقام التواصل'!$A$6:$A$505,"client",'أرقام التواصل'!$B$6:$B$505,A9,'أرقام التواصل'!$C$6:$C$505,1))=0),"REVIEW","READY")))) | BA9: =IF(AZ9="","",IF(OR(AZ9="READY",AZ9="TO_PROPOSED"),"",IF(AZ9="SKIP","Skipped by decision",TRIM(IF(B9="","missing import_action; ","")&IF(A9="","missing migration_customer_key; ","")&IF(AND(A9<>"",COUNTIF($A$6:$A$505,A9)>1),"duplicate migration_customer_key; ","")&IF(AND(NOT(OR(B9="to_candidate",AV9="proposed_name")),E9=""),"missing branch_id; ","")&IF(AND(NOT(OR(B9="to_candidate",AV9="proposed_name")),G9=""),"missing first_name; ","")&IF(AND(NOT(OR(B9="to_candidate",AV9="proposed_name")),I9=""),"missing last_name; ","")&IF(AND(NOT(OR(B9="to_candidate",AV9="proposed_name")),U9=""),"missing final_geo_unit_id; ","")&IF(AV9="","missing final_destination; ","")&IF(AND(NOT(OR(B9="to_candidate",AV9="proposed_name")),(COUNTIFS('أرقام التواصل'!$A$6:$A$505,"client",'أرقام التواصل'!$B$6:$B$505,A9,'أرقام التواصل'!$I$6:$I$505,"TRUE")+COUNTIFS('أرقام التواصل'!$A$6:$A$505,"client",'أرقام التواصل'!$B$6:$B$505,A9,'أرقام التواصل'!$C$6:$C$505,1))=0),"missing primary contact in أرقام التواصل; ","")&IF(OR(B9="to_candidate",AV9="proposed_name"),IF(AW9="","missing proposed_move_reason; ","")&IF(AX9="","missing proposed_name_key; ",""),"")))))
K10: =IF(TRIM(G10&" "&H10&" "&I10&IF(J10<>""," ("&J10&")",""))="","",TRIM(G10&" "&H10&" "&I10&IF(J10<>""," ("&J10&")",""))) | U10: =IF(AND(L10="",N10="",P10="",R10=""),"",IF(R10<>"",R10,IF(P10<>"",P10,IF(N10<>"",N10,L10)))) | AZ10: =IF(AND(A10="",B10="",E10="",G10="",I10="",AV10="",AX10=""),"",IF(OR(B10="skip",AV10="skip"),"SKIP",IF(OR(B10="to_candidate",AV10="proposed_name"),IF(OR(A10="",AW10="",AX10="",COUNTIF($A$6:$A$505,A10)>1),"REVIEW","TO_PROPOSED"),IF(OR(B10="",A10="",E10="",G10="",I10="",U10="",AV10="",COUNTIF($A$6:$A$505,A10)>1,(COUNTIFS('أرقام التواصل'!$A$6:$A$505,"client",'أرقام التواصل'!$B$6:$B$505,A10,'أرقام التواصل'!$I$6:$I$505,"TRUE")+COUNTIFS('أرقام التواصل'!$A$6:$A$505,"client",'أرقام التواصل'!$B$6:$B$505,A10,'أرقام التواصل'!$C$6:$C$505,1))=0),"REVIEW","READY")))) | BA10: =IF(AZ10="","",IF(OR(AZ10="READY",AZ10="TO_PROPOSED"),"",IF(AZ10="SKIP","Skipped by decision",TRIM(IF(B10="","missing import_action; ","")&IF(A10="","missing migration_customer_key; ","")&IF(AND(A10<>"",COUNTIF($A$6:$A$505,A10)>1),"duplicate migration_customer_key; ","")&IF(AND(NOT(OR(B10="to_candidate",AV10="proposed_name")),E10=""),"missing branch_id; ","")&IF(AND(NOT(OR(B10="to_candidate",AV10="proposed_name")),G10=""),"missing first_name; ","")&IF(AND(NOT(OR(B10="to_candidate",AV10="proposed_name")),I10=""),"missing last_name; ","")&IF(AND(NOT(OR(B10="to_candidate",AV10="proposed_name")),U10=""),"missing final_geo_unit_id; ","")&IF(AV10="","missing final_destination; ","")&IF(AND(NOT(OR(B10="to_candidate",AV10="proposed_name")),(COUNTIFS('أرقام التواصل'!$A$6:$A$505,"client",'أرقام التواصل'!$B$6:$B$505,A10,'أرقام التواصل'!$I$6:$I$505,"TRUE")+COUNTIFS('أرقام التواصل'!$A$6:$A$505,"client",'أرقام التواصل'!$B$6:$B$505,A10,'أرقام التواصل'!$C$6:$C$505,1))=0),"missing primary contact in أرقام التواصل; ","")&IF(OR(B10="to_candidate",AV10="proposed_name"),IF(AW10="","missing proposed_move_reason; ","")&IF(AX10="","missing proposed_name_key; ",""),"")))))
K11: =IF(TRIM(G11&" "&H11&" "&I11&IF(J11<>""," ("&J11&")",""))="","",TRIM(G11&" "&H11&" "&I11&IF(J11<>""," ("&J11&")",""))) | U11: =IF(AND(L11="",N11="",P11="",R11=""),"",IF(R11<>"",R11,IF(P11<>"",P11,IF(N11<>"",N11,L11)))) | AZ11: =IF(AND(A11="",B11="",E11="",G11="",I11="",AV11="",AX11=""),"",IF(OR(B11="skip",AV11="skip"),"SKIP",IF(OR(B11="to_candidate",AV11="proposed_name"),IF(OR(A11="",AW11="",AX11="",COUNTIF($A$6:$A$505,A11)>1),"REVIEW","TO_PROPOSED"),IF(OR(B11="",A11="",E11="",G11="",I11="",U11="",AV11="",COUNTIF($A$6:$A$505,A11)>1,(COUNTIFS('أرقام التواصل'!$A$6:$A$505,"client",'أرقام التواصل'!$B$6:$B$505,A11,'أرقام التواصل'!$I$6:$I$505,"TRUE")+COUNTIFS('أرقام التواصل'!$A$6:$A$505,"client",'أرقام التواصل'!$B$6:$B$505,A11,'أرقام التواصل'!$C$6:$C$505,1))=0),"REVIEW","READY")))) | BA11: =IF(AZ11="","",IF(OR(AZ11="READY",AZ11="TO_PROPOSED"),"",IF(AZ11="SKIP","Skipped by decision",TRIM(IF(B11="","missing import_action; ","")&IF(A11="","missing migration_customer_key; ","")&IF(AND(A11<>"",COUNTIF($A$6:$A$505,A11)>1),"duplicate migration_customer_key; ","")&IF(AND(NOT(OR(B11="to_candidate",AV11="proposed_name")),E11=""),"missing branch_id; ","")&IF(AND(NOT(OR(B11="to_candidate",AV11="proposed_name")),G11=""),"missing first_name; ","")&IF(AND(NOT(OR(B11="to_candidate",AV11="proposed_name")),I11=""),"missing last_name; ","")&IF(AND(NOT(OR(B11="to_candidate",AV11="proposed_name")),U11=""),"missing final_geo_unit_id; ","")&IF(AV11="","missing final_destination; ","")&IF(AND(NOT(OR(B11="to_candidate",AV11="proposed_name")),(COUNTIFS('أرقام التواصل'!$A$6:$A$505,"client",'أرقام التواصل'!$B$6:$B$505,A11,'أرقام التواصل'!$I$6:$I$505,"TRUE")+COUNTIFS('أرقام التواصل'!$A$6:$A$505,"client",'أرقام التواصل'!$B$6:$B$505,A11,'أرقام التواصل'!$C$6:$C$505,1))=0),"missing primary contact in أرقام التواصل; ","")&IF(OR(B11="to_candidate",AV11="proposed_name"),IF(AW11="","missing proposed_move_reason; ","")&IF(AX11="","missing proposed_name_key; ",""),"")))))
K12: =IF(TRIM(G12&" "&H12&" "&I12&IF(J12<>""," ("&J12&")",""))="","",TRIM(G12&" "&H12&" "&I12&IF(J12<>""," ("&J12&")",""))) | U12: =IF(AND(L12="",N12="",P12="",R12=""),"",IF(R12<>"",R12,IF(P12<>"",P12,IF(N12<>"",N12,L12)))) | AZ12: =IF(AND(A12="",B12="",E12="",G12="",I12="",AV12="",AX12=""),"",IF(OR(B12="skip",AV12="skip"),"SKIP",IF(OR(B12="to_candidate",AV12="proposed_name"),IF(OR(A12="",AW12="",AX12="",COUNTIF($A$6:$A$505,A12)>1),"REVIEW","TO_PROPOSED"),IF(OR(B12="",A12="",E12="",G12="",I12="",U12="",AV12="",COUNTIF($A$6:$A$505,A12)>1,(COUNTIFS('أرقام التواصل'!$A$6:$A$505,"client",'أرقام التواصل'!$B$6:$B$505,A12,'أرقام التواصل'!$I$6:$I$505,"TRUE")+COUNTIFS('أرقام التواصل'!$A$6:$A$505,"client",'أرقام التواصل'!$B$6:$B$505,A12,'أرقام التواصل'!$C$6:$C$505,1))=0),"REVIEW","READY")))) | BA12: =IF(AZ12="","",IF(OR(AZ12="READY",AZ12="TO_PROPOSED"),"",IF(AZ12="SKIP","Skipped by decision",TRIM(IF(B12="","missing import_action; ","")&IF(A12="","missing migration_customer_key; ","")&IF(AND(A12<>"",COUNTIF($A$6:$A$505,A12)>1),"duplicate migration_customer_key; ","")&IF(AND(NOT(OR(B12="to_candidate",AV12="proposed_name")),E12=""),"missing branch_id; ","")&IF(AND(NOT(OR(B12="to_candidate",AV12="proposed_name")),G12=""),"missing first_name; ","")&IF(AND(NOT(OR(B12="to_candidate",AV12="proposed_name")),I12=""),"missing last_name; ","")&IF(AND(NOT(OR(B12="to_candidate",AV12="proposed_name")),U12=""),"missing final_geo_unit_id; ","")&IF(AV12="","missing final_destination; ","")&IF(AND(NOT(OR(B12="to_candidate",AV12="proposed_name")),(COUNTIFS('أرقام التواصل'!$A$6:$A$505,"client",'أرقام التواصل'!$B$6:$B$505,A12,'أرقام التواصل'!$I$6:$I$505,"TRUE")+COUNTIFS('أرقام التواصل'!$A$6:$A$505,"client",'أرقام التواصل'!$B$6:$B$505,A12,'أرقام التواصل'!$C$6:$C$505,1))=0),"missing primary contact in أرقام التواصل; ","")&IF(OR(B12="to_candidate",AV12="proposed_name"),IF(AW12="","missing proposed_move_reason; ","")&IF(AX12="","missing proposed_name_key; ",""),"")))))
K13: =IF(TRIM(G13&" "&H13&" "&I13&IF(J13<>""," ("&J13&")",""))="","",TRIM(G13&" "&H13&" "&I13&IF(J13<>""," ("&J13&")",""))) | U13: =IF(AND(L13="",N13="",P13="",R13=""),"",IF(R13<>"",R13,IF(P13<>"",P13,IF(N13<>"",N13,L13)))) | AZ13: =IF(AND(A13="",B13="",E13="",G13="",I13="",AV13="",AX13=""),"",IF(OR(B13="skip",AV13="skip"),"SKIP",IF(OR(B13="to_candidate",AV13="proposed_name"),IF(OR(A13="",AW13="",AX13="",COUNTIF($A$6:$A$505,A13)>1),"REVIEW","TO_PROPOSED"),IF(OR(B13="",A13="",E13="",G13="",I13="",U13="",AV13="",COUNTIF($A$6:$A$505,A13)>1,(COUNTIFS('أرقام التواصل'!$A$6:$A$505,"client",'أرقام التواصل'!$B$6:$B$505,A13,'أرقام التواصل'!$I$6:$I$505,"TRUE")+COUNTIFS('أرقام التواصل'!$A$6:$A$505,"client",'أرقام التواصل'!$B$6:$B$505,A13,'أرقام التواصل'!$C$6:$C$505,1))=0),"REVIEW","READY")))) | BA13: =IF(AZ13="","",IF(OR(AZ13="READY",AZ13="TO_PROPOSED"),"",IF(AZ13="SKIP","Skipped by decision",TRIM(IF(B13="","missing import_action; ","")&IF(A13="","missing migration_customer_key; ","")&IF(AND(A13<>"",COUNTIF($A$6:$A$505,A13)>1),"duplicate migration_customer_key; ","")&IF(AND(NOT(OR(B13="to_candidate",AV13="proposed_name")),E13=""),"missing branch_id; ","")&IF(AND(NOT(OR(B13="to_candidate",AV13="proposed_name")),G13=""),"missing first_name; ","")&IF(AND(NOT(OR(B13="to_candidate",AV13="proposed_name")),I13=""),"missing last_name; ","")&IF(AND(NOT(OR(B13="to_candidate",AV13="proposed_name")),U13=""),"missing final_geo_unit_id; ","")&IF(AV13="","missing final_destination; ","")&IF(AND(NOT(OR(B13="to_candidate",AV13="proposed_name")),(COUNTIFS('أرقام التواصل'!$A$6:$A$505,"client",'أرقام التواصل'!$B$6:$B$505,A13,'أرقام التواصل'!$I$6:$I$505,"TRUE")+COUNTIFS('أرقام التواصل'!$A$6:$A$505,"client",'أرقام التواصل'!$B$6:$B$505,A13,'أرقام التواصل'!$C$6:$C$505,1))=0),"missing primary contact in أرقام التواصل; ","")&IF(OR(B13="to_candidate",AV13="proposed_name"),IF(AW13="","missing proposed_move_reason; ","")&IF(AX13="","missing proposed_name_key; ",""),"")))))
K14: =IF(TRIM(G14&" "&H14&" "&I14&IF(J14<>""," ("&J14&")",""))="","",TRIM(G14&" "&H14&" "&I14&IF(J14<>""," ("&J14&")",""))) | U14: =IF(AND(L14="",N14="",P14="",R14=""),"",IF(R14<>"",R14,IF(P14<>"",P14,IF(N14<>"",N14,L14)))) | AZ14: =IF(AND(A14="",B14="",E14="",G14="",I14="",AV14="",AX14=""),"",IF(OR(B14="skip",AV14="skip"),"SKIP",IF(OR(B14="to_candidate",AV14="proposed_name"),IF(OR(A14="",AW14="",AX14="",COUNTIF($A$6:$A$505,A14)>1),"REVIEW","TO_PROPOSED"),IF(OR(B14="",A14="",E14="",G14="",I14="",U14="",AV14="",COUNTIF($A$6:$A$505,A14)>1,(COUNTIFS('أرقام التواصل'!$A$6:$A$505,"client",'أرقام التواصل'!$B$6:$B$505,A14,'أرقام التواصل'!$I$6:$I$505,"TRUE")+COUNTIFS('أرقام التواصل'!$A$6:$A$505,"client",'أرقام التواصل'!$B$6:$B$505,A14,'أرقام التواصل'!$C$6:$C$505,1))=0),"REVIEW","READY")))) | BA14: =IF(AZ14="","",IF(OR(AZ14="READY",AZ14="TO_PROPOSED"),"",IF(AZ14="SKIP","Skipped by decision",TRIM(IF(B14="","missing import_action; ","")&IF(A14="","missing migration_customer_key; ","")&IF(AND(A14<>"",COUNTIF($A$6:$A$505,A14)>1),"duplicate migration_customer_key; ","")&IF(AND(NOT(OR(B14="to_candidate",AV14="proposed_name")),E14=""),"missing branch_id; ","")&IF(AND(NOT(OR(B14="to_candidate",AV14="proposed_name")),G14=""),"missing first_name; ","")&IF(AND(NOT(OR(B14="to_candidate",AV14="proposed_name")),I14=""),"missing last_name; ","")&IF(AND(NOT(OR(B14="to_candidate",AV14="proposed_name")),U14=""),"missing final_geo_unit_id; ","")&IF(AV14="","missing final_destination; ","")&IF(AND(NOT(OR(B14="to_candidate",AV14="proposed_name")),(COUNTIFS('أرقام التواصل'!$A$6:$A$505,"client",'أرقام التواصل'!$B$6:$B$505,A14,'أرقام التواصل'!$I$6:$I$505,"TRUE")+COUNTIFS('أرقام التواصل'!$A$6:$A$505,"client",'أرقام التواصل'!$B$6:$B$505,A14,'أرقام التواصل'!$C$6:$C$505,1))=0),"missing primary contact in أرقام التواصل; ","")&IF(OR(B14="to_candidate",AV14="proposed_name"),IF(AW14="","missing proposed_move_reason; ","")&IF(AX14="","missing proposed_name_key; ",""),"")))))
K15: =IF(TRIM(G15&" "&H15&" "&I15&IF(J15<>""," ("&J15&")",""))="","",TRIM(G15&" "&H15&" "&I15&IF(J15<>""," ("&J15&")",""))) | U15: =IF(AND(L15="",N15="",P15="",R15=""),"",IF(R15<>"",R15,IF(P15<>"",P15,IF(N15<>"",N15,L15)))) | AZ15: =IF(AND(A15="",B15="",E15="",G15="",I15="",AV15="",AX15=""),"",IF(OR(B15="skip",AV15="skip"),"SKIP",IF(OR(B15="to_candidate",AV15="proposed_name"),IF(OR(A15="",AW15="",AX15="",COUNTIF($A$6:$A$505,A15)>1),"REVIEW","TO_PROPOSED"),IF(OR(B15="",A15="",E15="",G15="",I15="",U15="",AV15="",COUNTIF($A$6:$A$505,A15)>1,(COUNTIFS('أرقام التواصل'!$A$6:$A$505,"client",'أرقام التواصل'!$B$6:$B$505,A15,'أرقام التواصل'!$I$6:$I$505,"TRUE")+COUNTIFS('أرقام التواصل'!$A$6:$A$505,"client",'أرقام التواصل'!$B$6:$B$505,A15,'أرقام التواصل'!$C$6:$C$505,1))=0),"REVIEW","READY")))) | BA15: =IF(AZ15="","",IF(OR(AZ15="READY",AZ15="TO_PROPOSED"),"",IF(AZ15="SKIP","Skipped by decision",TRIM(IF(B15="","missing import_action; ","")&IF(A15="","missing migration_customer_key; ","")&IF(AND(A15<>"",COUNTIF($A$6:$A$505,A15)>1),"duplicate migration_customer_key; ","")&IF(AND(NOT(OR(B15="to_candidate",AV15="proposed_name")),E15=""),"missing branch_id; ","")&IF(AND(NOT(OR(B15="to_candidate",AV15="proposed_name")),G15=""),"missing first_name; ","")&IF(AND(NOT(OR(B15="to_candidate",AV15="proposed_name")),I15=""),"missing last_name; ","")&IF(AND(NOT(OR(B15="to_candidate",AV15="proposed_name")),U15=""),"missing final_geo_unit_id; ","")&IF(AV15="","missing final_destination; ","")&IF(AND(NOT(OR(B15="to_candidate",AV15="proposed_name")),(COUNTIFS('أرقام التواصل'!$A$6:$A$505,"client",'أرقام التواصل'!$B$6:$B$505,A15,'أرقام التواصل'!$I$6:$I$505,"TRUE")+COUNTIFS('أرقام التواصل'!$A$6:$A$505,"client",'أرقام التواصل'!$B$6:$B$505,A15,'أرقام التواصل'!$C$6:$C$505,1))=0),"missing primary contact in أرقام التواصل; ","")&IF(OR(B15="to_candidate",AV15="proposed_name"),IF(AW15="","missing proposed_move_reason; ","")&IF(AX15="","missing proposed_name_key; ",""),"")))))
K16: =IF(TRIM(G16&" "&H16&" "&I16&IF(J16<>""," ("&J16&")",""))="","",TRIM(G16&" "&H16&" "&I16&IF(J16<>""," ("&J16&")",""))) | U16: =IF(AND(L16="",N16="",P16="",R16=""),"",IF(R16<>"",R16,IF(P16<>"",P16,IF(N16<>"",N16,L16)))) | AZ16: =IF(AND(A16="",B16="",E16="",G16="",I16="",AV16="",AX16=""),"",IF(OR(B16="skip",AV16="skip"),"SKIP",IF(OR(B16="to_candidate",AV16="proposed_name"),IF(OR(A16="",AW16="",AX16="",COUNTIF($A$6:$A$505,A16)>1),"REVIEW","TO_PROPOSED"),IF(OR(B16="",A16="",E16="",G16="",I16="",U16="",AV16="",COUNTIF($A$6:$A$505,A16)>1,(COUNTIFS('أرقام التواصل'!$A$6:$A$505,"client",'أرقام التواصل'!$B$6:$B$505,A16,'أرقام التواصل'!$I$6:$I$505,"TRUE")+COUNTIFS('أرقام التواصل'!$A$6:$A$505,"client",'أرقام التواصل'!$B$6:$B$505,A16,'أرقام التواصل'!$C$6:$C$505,1))=0),"REVIEW","READY")))) | BA16: =IF(AZ16="","",IF(OR(AZ16="READY",AZ16="TO_PROPOSED"),"",IF(AZ16="SKIP","Skipped by decision",TRIM(IF(B16="","missing import_action; ","")&IF(A16="","missing migration_customer_key; ","")&IF(AND(A16<>"",COUNTIF($A$6:$A$505,A16)>1),"duplicate migration_customer_key; ","")&IF(AND(NOT(OR(B16="to_candidate",AV16="proposed_name")),E16=""),"missing branch_id; ","")&IF(AND(NOT(OR(B16="to_candidate",AV16="proposed_name")),G16=""),"missing first_name; ","")&IF(AND(NOT(OR(B16="to_candidate",AV16="proposed_name")),I16=""),"missing last_name; ","")&IF(AND(NOT(OR(B16="to_candidate",AV16="proposed_name")),U16=""),"missing final_geo_unit_id; ","")&IF(AV16="","missing final_destination; ","")&IF(AND(NOT(OR(B16="to_candidate",AV16="proposed_name")),(COUNTIFS('أرقام التواصل'!$A$6:$A$505,"client",'أرقام التواصل'!$B$6:$B$505,A16,'أرقام التواصل'!$I$6:$I$505,"TRUE")+COUNTIFS('أرقام التواصل'!$A$6:$A$505,"client",'أرقام التواصل'!$B$6:$B$505,A16,'أرقام التواصل'!$C$6:$C$505,1))=0),"missing primary contact in أرقام التواصل; ","")&IF(OR(B16="to_candidate",AV16="proposed_name"),IF(AW16="","missing proposed_move_reason; ","")&IF(AX16="","missing proposed_name_key; ",""),"")))))
K17: =IF(TRIM(G17&" "&H17&" "&I17&IF(J17<>""," ("&J17&")",""))="","",TRIM(G17&" "&H17&" "&I17&IF(J17<>""," ("&J17&")",""))) | U17: =IF(AND(L17="",N17="",P17="",R17=""),"",IF(R17<>"",R17,IF(P17<>"",P17,IF(N17<>"",N17,L17)))) | AZ17: =IF(AND(A17="",B17="",E17="",G17="",I17="",AV17="",AX17=""),"",IF(OR(B17="skip",AV17="skip"),"SKIP",IF(OR(B17="to_candidate",AV17="proposed_name"),IF(OR(A17="",AW17="",AX17="",COUNTIF($A$6:$A$505,A17)>1),"REVIEW","TO_PROPOSED"),IF(OR(B17="",A17="",E17="",G17="",I17="",U17="",AV17="",COUNTIF($A$6:$A$505,A17)>1,(COUNTIFS('أرقام التواصل'!$A$6:$A$505,"client",'أرقام التواصل'!$B$6:$B$505,A17,'أرقام التواصل'!$I$6:$I$505,"TRUE")+COUNTIFS('أرقام التواصل'!$A$6:$A$505,"client",'أرقام التواصل'!$B$6:$B$505,A17,'أرقام التواصل'!$C$6:$C$505,1))=0),"REVIEW","READY")))) | BA17: =IF(AZ17="","",IF(OR(AZ17="READY",AZ17="TO_PROPOSED"),"",IF(AZ17="SKIP","Skipped by decision",TRIM(IF(B17="","missing import_action; ","")&IF(A17="","missing migration_customer_key; ","")&IF(AND(A17<>"",COUNTIF($A$6:$A$505,A17)>1),"duplicate migration_customer_key; ","")&IF(AND(NOT(OR(B17="to_candidate",AV17="proposed_name")),E17=""),"missing branch_id; ","")&IF(AND(NOT(OR(B17="to_candidate",AV17="proposed_name")),G17=""),"missing first_name; ","")&IF(AND(NOT(OR(B17="to_candidate",AV17="proposed_name")),I17=""),"missing last_name; ","")&IF(AND(NOT(OR(B17="to_candidate",AV17="proposed_name")),U17=""),"missing final_geo_unit_id; ","")&IF(AV17="","missing final_destination; ","")&IF(AND(NOT(OR(B17="to_candidate",AV17="proposed_name")),(COUNTIFS('أرقام التواصل'!$A$6:$A$505,"client",'أرقام التواصل'!$B$6:$B$505,A17,'أرقام التواصل'!$I$6:$I$505,"TRUE")+COUNTIFS('أرقام التواصل'!$A$6:$A$505,"client",'أرقام التواصل'!$B$6:$B$505,A17,'أرقام التواصل'!$C$6:$C$505,1))=0),"missing primary contact in أرقام التواصل; ","")&IF(OR(B17="to_candidate",AV17="proposed_name"),IF(AW17="","missing proposed_move_reason; ","")&IF(AX17="","missing proposed_name_key; ",""),"")))))
K18: =IF(TRIM(G18&" "&H18&" "&I18&IF(J18<>""," ("&J18&")",""))="","",TRIM(G18&" "&H18&" "&I18&IF(J18<>""," ("&J18&")",""))) | U18: =IF(AND(L18="",N18="",P18="",R18=""),"",IF(R18<>"",R18,IF(P18<>"",P18,IF(N18<>"",N18,L18)))) | AZ18: =IF(AND(A18="",B18="",E18="",G18="",I18="",AV18="",AX18=""),"",IF(OR(B18="skip",AV18="skip"),"SKIP",IF(OR(B18="to_candidate",AV18="proposed_name"),IF(OR(A18="",AW18="",AX18="",COUNTIF($A$6:$A$505,A18)>1),"REVIEW","TO_PROPOSED"),IF(OR(B18="",A18="",E18="",G18="",I18="",U18="",AV18="",COUNTIF($A$6:$A$505,A18)>1,(COUNTIFS('أرقام التواصل'!$A$6:$A$505,"client",'أرقام التواصل'!$B$6:$B$505,A18,'أرقام التواصل'!$I$6:$I$505,"TRUE")+COUNTIFS('أرقام التواصل'!$A$6:$A$505,"client",'أرقام التواصل'!$B$6:$B$505,A18,'أرقام التواصل'!$C$6:$C$505,1))=0),"REVIEW","READY")))) | BA18: =IF(AZ18="","",IF(OR(AZ18="READY",AZ18="TO_PROPOSED"),"",IF(AZ18="SKIP","Skipped by decision",TRIM(IF(B18="","missing import_action; ","")&IF(A18="","missing migration_customer_key; ","")&IF(AND(A18<>"",COUNTIF($A$6:$A$505,A18)>1),"duplicate migration_customer_key; ","")&IF(AND(NOT(OR(B18="to_candidate",AV18="proposed_name")),E18=""),"missing branch_id; ","")&IF(AND(NOT(OR(B18="to_candidate",AV18="proposed_name")),G18=""),"missing first_name; ","")&IF(AND(NOT(OR(B18="to_candidate",AV18="proposed_name")),I18=""),"missing last_name; ","")&IF(AND(NOT(OR(B18="to_candidate",AV18="proposed_name")),U18=""),"missing final_geo_unit_id; ","")&IF(AV18="","missing final_destination; ","")&IF(AND(NOT(OR(B18="to_candidate",AV18="proposed_name")),(COUNTIFS('أرقام التواصل'!$A$6:$A$505,"client",'أرقام التواصل'!$B$6:$B$505,A18,'أرقام التواصل'!$I$6:$I$505,"TRUE")+COUNTIFS('أرقام التواصل'!$A$6:$A$505,"client",'أرقام التواصل'!$B$6:$B$505,A18,'أرقام التواصل'!$C$6:$C$505,1))=0),"missing primary contact in أرقام التواصل; ","")&IF(OR(B18="to_candidate",AV18="proposed_name"),IF(AW18="","missing proposed_move_reason; ","")&IF(AX18="","missing proposed_name_key; ",""),"")))))
K19: =IF(TRIM(G19&" "&H19&" "&I19&IF(J19<>""," ("&J19&")",""))="","",TRIM(G19&" "&H19&" "&I19&IF(J19<>""," ("&J19&")",""))) | U19: =IF(AND(L19="",N19="",P19="",R19=""),"",IF(R19<>"",R19,IF(P19<>"",P19,IF(N19<>"",N19,L19)))) | AZ19: =IF(AND(A19="",B19="",E19="",G19="",I19="",AV19="",AX19=""),"",IF(OR(B19="skip",AV19="skip"),"SKIP",IF(OR(B19="to_candidate",AV19="proposed_name"),IF(OR(A19="",AW19="",AX19="",COUNTIF($A$6:$A$505,A19)>1),"REVIEW","TO_PROPOSED"),IF(OR(B19="",A19="",E19="",G19="",I19="",U19="",AV19="",COUNTIF($A$6:$A$505,A19)>1,(COUNTIFS('أرقام التواصل'!$A$6:$A$505,"client",'أرقام التواصل'!$B$6:$B$505,A19,'أرقام التواصل'!$I$6:$I$505,"TRUE")+COUNTIFS('أرقام التواصل'!$A$6:$A$505,"client",'أرقام التواصل'!$B$6:$B$505,A19,'أرقام التواصل'!$C$6:$C$505,1))=0),"REVIEW","READY")))) | BA19: =IF(AZ19="","",IF(OR(AZ19="READY",AZ19="TO_PROPOSED"),"",IF(AZ19="SKIP","Skipped by decision",TRIM(IF(B19="","missing import_action; ","")&IF(A19="","missing migration_customer_key; ","")&IF(AND(A19<>"",COUNTIF($A$6:$A$505,A19)>1),"duplicate migration_customer_key; ","")&IF(AND(NOT(OR(B19="to_candidate",AV19="proposed_name")),E19=""),"missing branch_id; ","")&IF(AND(NOT(OR(B19="to_candidate",AV19="proposed_name")),G19=""),"missing first_name; ","")&IF(AND(NOT(OR(B19="to_candidate",AV19="proposed_name")),I19=""),"missing last_name; ","")&IF(AND(NOT(OR(B19="to_candidate",AV19="proposed_name")),U19=""),"missing final_geo_unit_id; ","")&IF(AV19="","missing final_destination; ","")&IF(AND(NOT(OR(B19="to_candidate",AV19="proposed_name")),(COUNTIFS('أرقام التواصل'!$A$6:$A$505,"client",'أرقام التواصل'!$B$6:$B$505,A19,'أرقام التواصل'!$I$6:$I$505,"TRUE")+COUNTIFS('أرقام التواصل'!$A$6:$A$505,"client",'أرقام التواصل'!$B$6:$B$505,A19,'أرقام التواصل'!$C$6:$C$505,1))=0),"missing primary contact in أرقام التواصل; ","")&IF(OR(B19="to_candidate",AV19="proposed_name"),IF(AW19="","missing proposed_move_reason; ","")&IF(AX19="","missing proposed_name_key; ",""),"")))))
... K505: =IF(TRIM(G505&" "&H505&" "&I505&IF(J505<>""," ("&J505&")",""))="","",TRIM(G505&" "&H505&" "&I505&IF(J505<>""," ("&J505&")",""))) | U505: =IF(AND(L505="",N505="",P505="",R505=""),"",IF(R505<>"",R505,IF(P505<>"",P505,IF(N505<>"",N505,L505)))) | AZ505: =IF(AND(A505="",B505="",E505="",G505="",I505="",AV505="",AX505=""),"",IF(OR(B505="skip",AV505="skip"),"SKIP",IF(OR(B505="to_candidate",AV505="proposed_name"),IF(OR(A505="",AW505="",AX505="",COUNTIF($A$6:$A$505,A505)>1),"REVIEW","TO_PROPOSED"),IF(OR(B505="",A505="",E505="",G505="",I505="",U505="",AV505="",COUNTIF($A$6:$A$505,A505)>1,(COUNTIFS('أرقام التواصل'!$A$6:$A$505,"client",'أرقام التواصل'!$B$6:$B$505,A505,'أرقام التواصل'!$I$6:$I$505,"TRUE")+COUNTIFS('أرقام التواصل'!$A$6:$A$505,"client",'أرقام التواصل'!$B$6:$B$505,A505,'أرقام التواصل'!$C$6:$C$505,1))=0),"REVIEW","READY")))) | BA505: =IF(AZ505="","",IF(OR(AZ505="READY",AZ505="TO_PROPOSED"),"",IF(AZ505="SKIP","Skipped by decision",TRIM(IF(B505="","missing import_action; ","")&IF(A505="","missing migration_customer_key; ","")&IF(AND(A505<>"",COUNTIF($A$6:$A$505,A505)>1),"duplicate migration_customer_key; ","")&IF(AND(NOT(OR(B505="to_candidate",AV505="proposed_name")),E505=""),"missing branch_id; ","")&IF(AND(NOT(OR(B505="to_candidate",AV505="proposed_name")),G505=""),"missing first_name; ","")&IF(AND(NOT(OR(B505="to_candidate",AV505="proposed_name")),I505=""),"missing last_name; ","")&IF(AND(NOT(OR(B505="to_candidate",AV505="proposed_name")),U505=""),"missing final_geo_unit_id; ","")&IF(AV505="","missing final_destination; ","")&IF(AND(NOT(OR(B505="to_candidate",AV505="proposed_name")),(COUNTIFS('أرقام التواصل'!$A$6:$A$505,"client",'أرقام التواصل'!$B$6:$B$505,A505,'أرقام التواصل'!$I$6:$I$505,"TRUE")+COUNTIFS('أرقام التواصل'!$A$6:$A$505,"client",'أرقام التواصل'!$B$6:$B$505,A505,'أرقام التواصل'!$C$6:$C$505,1))=0),"missing primary contact in أرقام التواصل; ","")&IF(OR(B505="to_candidate",AV505="proposed_name"),IF(AW505="","missing proposed_move_reason; ","")&IF(AX505="","missing proposed_name_key; ",""),"")))))

Sheet أرقام التواصل
A1: أرقام التواصل | B1: أرقام التواصل | C1: أرقام التواصل | D1: أرقام التواصل | E1: أرقام التواصل | F1: أرقام التواصل | G1: أرقام التواصل | H1: أرقام التواصل | I1: أرقام التواصل | J1: أرقام التواصل | K1: أرقام التواصل | L1: أرقام التواصل | M1: أرقام التواصل | N1: أرقام التواصل
A2: كل الأرقام هنا للزبائن والأسماء المقترحة. اربط الصف عبر entity_type + entity_key. contact_order=1 هو الرقم الأساسي. | B2: كل الأرقام هنا للزبائن والأسماء المقترحة. اربط الصف عبر entity_type + entity_key. contact_order=1 هو الرقم الأساسي. | C2: كل الأرقام هنا للزبائن والأسماء المقترحة. اربط الصف عبر entity_type + entity_key. contact_order=1 هو الرقم الأساسي. | D2: كل الأرقام هنا للزبائن والأسماء المقترحة. اربط الصف عبر entity_type + entity_key. contact_order=1 هو الرقم الأساسي. | E2: كل الأرقام هنا للزبائن والأسماء المقترحة. اربط الصف عبر entity_type + entity_key. contact_order=1 هو الرقم الأساسي. | F2: كل الأرقام هنا للزبائن والأسماء المقترحة. اربط الصف عبر entity_type + entity_key. contact_order=1 هو الرقم الأساسي. | G2: كل الأرقام هنا للزبائن والأسماء المقترحة. اربط الصف عبر entity_type + entity_key. contact_order=1 هو الرقم الأساسي. | H2: كل الأرقام هنا للزبائن والأسماء المقترحة. اربط الصف عبر entity_type + entity_key. contact_order=1 هو الرقم الأساسي. | I2: كل الأرقام هنا للزبائن والأسماء المقترحة. اربط الصف عبر entity_type + entity_key. contact_order=1 هو الرقم الأساسي. | J2: كل الأرقام هنا للزبائن والأسماء المقترحة. اربط الصف عبر entity_type + entity_key. contact_order=1 هو الرقم الأساسي. | K2: كل الأرقام هنا للزبائن والأسماء المقترحة. اربط الصف عبر entity_type + entity_key. contact_order=1 هو الرقم الأساسي. | L2: كل الأرقام هنا للزبائن والأسماء المقترحة. اربط الصف عبر entity_type + entity_key. contact_order=1 هو الرقم الأساسي. | M2: كل الأرقام هنا للزبائن والأسماء المقترحة. اربط الصف عبر entity_type + entity_key. contact_order=1 هو الرقم الأساسي. | N2: كل الأرقام هنا للزبائن والأسماء المقترحة. اربط الصف عبر entity_type + entity_key. contact_order=1 هو الرقم الأساسي.
A3: entity_type | B3: entity_key | C3: contact_order | D3: contact_type | E3: number | F3: area_code | G3: label | H3: has_whatsapp | I3: is_primary | J3: status | K3: cleanup_status | L3: notes | M3: row_status | N3: row_issues
A4: ربط | B4: ربط | C4: التواصل | D4: التواصل | E4: التواصل | F4: التواصل | G4: التواصل | H4: التواصل | I4: التواصل | J4: التواصل | K4: مراجعة | L4: مراجعة | M4: مراجعة | N4: مراجعة
A5: نوع السجل | B5: مفتاح السجل | C5: ترتيب الرقم | D5: نوع الرقم | E5: الرقم | F5: رمز المنطقة | G5: وصف الرقم | H5: واتساب | I5: أساسي؟ | J5: حالة الرقم | K5: حالة التنظيف | L5: ملاحظات | M5: حالة الصف - تلقائي | N5: مشاكل الصف - تلقائي
A6: client | B6: CUST-0001 | C6: 1 | D6: mobile | E6: 912345678 | G6: أساسي | H6: TRUE | I6: TRUE | J6: active | K6: cleaned | L6: الرقم الأساسي للزبون | M6: =IF(AND(A6="",B6="",E6=""),"",IF(OR(A6="",B6="",C6="",D6="",E6="",J6="",AND(A6="client",COUNTIF(الزبائن!$A$6:$A$505,B6)=0),AND(A6="proposed_name",COUNTIF('أسماء مقترحة'!$A$6:$A$505,B6)=0),AND(D6="mobile",J6<>"invalid",NOT(OR(AND(LEN(E6&"")=10,LEFT(E6&"",2)="09"),AND(LEN(E6&"")=9,LEFT(E6&"",1)="9")))),COUNTIFS($A$6:$A$505,A6,$B$6:$B$505,B6,$E$6:$E$505,E6)>1),"REVIEW","READY")) -> READY | N6: =IF(M6="","",IF(M6="READY","",TRIM(IF(A6="","missing entity_type; ","")&IF(B6="","missing entity_key; ","")&IF(C6="","missing contact_order; ","")&IF(D6="","missing contact_type; ","")&IF(E6="","missing number; ","")&IF(J6="","missing status; ","")&IF(AND(A6="client",COUNTIF(الزبائن!$A$6:$A$505,B6)=0),"client key not found; ","")&IF(AND(A6="proposed_name",COUNTIF('أسماء مقترحة'!$A$6:$A$505,B6)=0),"proposed_name key not found; ","")&IF(AND(D6="mobile",J6<>"invalid",NOT(OR(AND(LEN(E6&"")=10,LEFT(E6&"",2)="09"),AND(LEN(E6&"")=9,LEFT(E6&"",1)="9")))),"mobile must be 09XXXXXXXX or status invalid; ","")&IF(COUNTIFS($A$6:$A$505,A6,$B$6:$B$505,B6,$E$6:$E$505,E6)>1,"duplicate number for same entity; ",""))))
A7: client | B7: CUST-0001 | C7: 2 | D7: landline | E7: 1234567 | F7: 011 | G7: منزل | H7: FALSE | I7: FALSE | J7: active | K7: cleaned | M7: =IF(AND(A7="",B7="",E7=""),"",IF(OR(A7="",B7="",C7="",D7="",E7="",J7="",AND(A7="client",COUNTIF(الزبائن!$A$6:$A$505,B7)=0),AND(A7="proposed_name",COUNTIF('أسماء مقترحة'!$A$6:$A$505,B7)=0),AND(D7="mobile",J7<>"invalid",NOT(OR(AND(LEN(E7&"")=10,LEFT(E7&"",2)="09"),AND(LEN(E7&"")=9,LEFT(E7&"",1)="9")))),COUNTIFS($A$6:$A$505,A7,$B$6:$B$505,B7,$E$6:$E$505,E7)>1),"REVIEW","READY")) -> READY | N7: =IF(M7="","",IF(M7="READY","",TRIM(IF(A7="","missing entity_type; ","")&IF(B7="","missing entity_key; ","")&IF(C7="","missing contact_order; ","")&IF(D7="","missing contact_type; ","")&IF(E7="","missing number; ","")&IF(J7="","missing status; ","")&IF(AND(A7="client",COUNTIF(الزبائن!$A$6:$A$505,B7)=0),"client key not found; ","")&IF(AND(A7="proposed_name",COUNTIF('أسماء مقترحة'!$A$6:$A$505,B7)=0),"proposed_name key not found; ","")&IF(AND(D7="mobile",J7<>"invalid",NOT(OR(AND(LEN(E7&"")=10,LEFT(E7&"",2)="09"),AND(LEN(E7&"")=9,LEFT(E7&"",1)="9")))),"mobile must be 09XXXXXXXX or status invalid; ","")&IF(COUNTIFS($A$6:$A$505,A7,$B$6:$B$505,B7,$E$6:$E$505,E7)>1,"duplicate number for same entity; ",""))))
A8: proposed_name | B8: PN-CUST-0002 | C8: 1 | D8: mobile | E8: 998765432 | G8: رقم من النظام القديم | H8: FALSE | I8: TRUE | J8: preferred | K8: review_needed | L8: يتأكد قبل التحويل لزبون | M8: =IF(AND(A8="",B8="",E8=""),"",IF(OR(A8="",B8="",C8="",D8="",E8="",J8="",AND(A8="client",COUNTIF(الزبائن!$A$6:$A$505,B8)=0),AND(A8="proposed_name",COUNTIF('أسماء مقترحة'!$A$6:$A$505,B8)=0),AND(D8="mobile",J8<>"invalid",NOT(OR(AND(LEN(E8&"")=10,LEFT(E8&"",2)="09"),AND(LEN(E8&"")=9,LEFT(E8&"",1)="9")))),COUNTIFS($A$6:$A$505,A8,$B$6:$B$505,B8,$E$6:$E$505,E8)>1),"REVIEW","READY")) -> READY | N8: =IF(M8="","",IF(M8="READY","",TRIM(IF(A8="","missing entity_type; ","")&IF(B8="","missing entity_key; ","")&IF(C8="","missing contact_order; ","")&IF(D8="","missing contact_type; ","")&IF(E8="","missing number; ","")&IF(J8="","missing status; ","")&IF(AND(A8="client",COUNTIF(الزبائن!$A$6:$A$505,B8)=0),"client key not found; ","")&IF(AND(A8="proposed_name",COUNTIF('أسماء مقترحة'!$A$6:$A$505,B8)=0),"proposed_name key not found; ","")&IF(AND(D8="mobile",J8<>"invalid",NOT(OR(AND(LEN(E8&"")=10,LEFT(E8&"",2)="09"),AND(LEN(E8&"")=9,LEFT(E8&"",1)="9")))),"mobile must be 09XXXXXXXX or status invalid; ","")&IF(COUNTIFS($A$6:$A$505,A8,$B$6:$B$505,B8,$E$6:$E$505,E8)>1,"duplicate number for same entity; ",""))))
M9: =IF(AND(A9="",B9="",E9=""),"",IF(OR(A9="",B9="",C9="",D9="",E9="",J9="",AND(A9="client",COUNTIF(الزبائن!$A$6:$A$505,B9)=0),AND(A9="proposed_name",COUNTIF('أسماء مقترحة'!$A$6:$A$505,B9)=0),AND(D9="mobile",J9<>"invalid",NOT(OR(AND(LEN(E9&"")=10,LEFT(E9&"",2)="09"),AND(LEN(E9&"")=9,LEFT(E9&"",1)="9")))),COUNTIFS($A$6:$A$505,A9,$B$6:$B$505,B9,$E$6:$E$505,E9)>1),"REVIEW","READY")) | N9: =IF(M9="","",IF(M9="READY","",TRIM(IF(A9="","missing entity_type; ","")&IF(B9="","missing entity_key; ","")&IF(C9="","missing contact_order; ","")&IF(D9="","missing contact_type; ","")&IF(E9="","missing number; ","")&IF(J9="","missing status; ","")&IF(AND(A9="client",COUNTIF(الزبائن!$A$6:$A$505,B9)=0),"client key not found; ","")&IF(AND(A9="proposed_name",COUNTIF('أسماء مقترحة'!$A$6:$A$505,B9)=0),"proposed_name key not found; ","")&IF(AND(D9="mobile",J9<>"invalid",NOT(OR(AND(LEN(E9&"")=10,LEFT(E9&"",2)="09"),AND(LEN(E9&"")=9,LEFT(E9&"",1)="9")))),"mobile must be 09XXXXXXXX or status invalid; ","")&IF(COUNTIFS($A$6:$A$505,A9,$B$6:$B$505,B9,$E$6:$E$505,E9)>1,"duplicate number for same entity; ",""))))
M10: =IF(AND(A10="",B10="",E10=""),"",IF(OR(A10="",B10="",C10="",D10="",E10="",J10="",AND(A10="client",COUNTIF(الزبائن!$A$6:$A$505,B10)=0),AND(A10="proposed_name",COUNTIF('أسماء مقترحة'!$A$6:$A$505,B10)=0),AND(D10="mobile",J10<>"invalid",NOT(OR(AND(LEN(E10&"")=10,LEFT(E10&"",2)="09"),AND(LEN(E10&"")=9,LEFT(E10&"",1)="9")))),COUNTIFS($A$6:$A$505,A10,$B$6:$B$505,B10,$E$6:$E$505,E10)>1),"REVIEW","READY")) | N10: =IF(M10="","",IF(M10="READY","",TRIM(IF(A10="","missing entity_type; ","")&IF(B10="","missing entity_key; ","")&IF(C10="","missing contact_order; ","")&IF(D10="","missing contact_type; ","")&IF(E10="","missing number; ","")&IF(J10="","missing status; ","")&IF(AND(A10="client",COUNTIF(الزبائن!$A$6:$A$505,B10)=0),"client key not found; ","")&IF(AND(A10="proposed_name",COUNTIF('أسماء مقترحة'!$A$6:$A$505,B10)=0),"proposed_name key not found; ","")&IF(AND(D10="mobile",J10<>"invalid",NOT(OR(AND(LEN(E10&"")=10,LEFT(E10&"",2)="09"),AND(LEN(E10&"")=9,LEFT(E10&"",1)="9")))),"mobile must be 09XXXXXXXX or status invalid; ","")&IF(COUNTIFS($A$6:$A$505,A10,$B$6:$B$505,B10,$E$6:$E$505,E10)>1,"duplicate number for same entity; ",""))))
M11: =IF(AND(A11="",B11="",E11=""),"",IF(OR(A11="",B11="",C11="",D11="",E11="",J11="",AND(A11="client",COUNTIF(الزبائن!$A$6:$A$505,B11)=0),AND(A11="proposed_name",COUNTIF('أسماء مقترحة'!$A$6:$A$505,B11)=0),AND(D11="mobile",J11<>"invalid",NOT(OR(AND(LEN(E11&"")=10,LEFT(E11&"",2)="09"),AND(LEN(E11&"")=9,LEFT(E11&"",1)="9")))),COUNTIFS($A$6:$A$505,A11,$B$6:$B$505,B11,$E$6:$E$505,E11)>1),"REVIEW","READY")) | N11: =IF(M11="","",IF(M11="READY","",TRIM(IF(A11="","missing entity_type; ","")&IF(B11="","missing entity_key; ","")&IF(C11="","missing contact_order; ","")&IF(D11="","missing contact_type; ","")&IF(E11="","missing number; ","")&IF(J11="","missing status; ","")&IF(AND(A11="client",COUNTIF(الزبائن!$A$6:$A$505,B11)=0),"client key not found; ","")&IF(AND(A11="proposed_name",COUNTIF('أسماء مقترحة'!$A$6:$A$505,B11)=0),"proposed_name key not found; ","")&IF(AND(D11="mobile",J11<>"invalid",NOT(OR(AND(LEN(E11&"")=10,LEFT(E11&"",2)="09"),AND(LEN(E11&"")=9,LEFT(E11&"",1)="9")))),"mobile must be 09XXXXXXXX or status invalid; ","")&IF(COUNTIFS($A$6:$A$505,A11,$B$6:$B$505,B11,$E$6:$E$505,E11)>1,"duplicate number for same entity; ",""))))
M12: =IF(AND(A12="",B12="",E12=""),"",IF(OR(A12="",B12="",C12="",D12="",E12="",J12="",AND(A12="client",COUNTIF(الزبائن!$A$6:$A$505,B12)=0),AND(A12="proposed_name",COUNTIF('أسماء مقترحة'!$A$6:$A$505,B12)=0),AND(D12="mobile",J12<>"invalid",NOT(OR(AND(LEN(E12&"")=10,LEFT(E12&"",2)="09"),AND(LEN(E12&"")=9,LEFT(E12&"",1)="9")))),COUNTIFS($A$6:$A$505,A12,$B$6:$B$505,B12,$E$6:$E$505,E12)>1),"REVIEW","READY")) | N12: =IF(M12="","",IF(M12="READY","",TRIM(IF(A12="","missing entity_type; ","")&IF(B12="","missing entity_key; ","")&IF(C12="","missing contact_order; ","")&IF(D12="","missing contact_type; ","")&IF(E12="","missing number; ","")&IF(J12="","missing status; ","")&IF(AND(A12="client",COUNTIF(الزبائن!$A$6:$A$505,B12)=0),"client key not found; ","")&IF(AND(A12="proposed_name",COUNTIF('أسماء مقترحة'!$A$6:$A$505,B12)=0),"proposed_name key not found; ","")&IF(AND(D12="mobile",J12<>"invalid",NOT(OR(AND(LEN(E12&"")=10,LEFT(E12&"",2)="09"),AND(LEN(E12&"")=9,LEFT(E12&"",1)="9")))),"mobile must be 09XXXXXXXX or status invalid; ","")&IF(COUNTIFS($A$6:$A$505,A12,$B$6:$B$505,B12,$E$6:$E$505,E12)>1,"duplicate number for same entity; ",""))))
M13: =IF(AND(A13="",B13="",E13=""),"",IF(OR(A13="",B13="",C13="",D13="",E13="",J13="",AND(A13="client",COUNTIF(الزبائن!$A$6:$A$505,B13)=0),AND(A13="proposed_name",COUNTIF('أسماء مقترحة'!$A$6:$A$505,B13)=0),AND(D13="mobile",J13<>"invalid",NOT(OR(AND(LEN(E13&"")=10,LEFT(E13&"",2)="09"),AND(LEN(E13&"")=9,LEFT(E13&"",1)="9")))),COUNTIFS($A$6:$A$505,A13,$B$6:$B$505,B13,$E$6:$E$505,E13)>1),"REVIEW","READY")) | N13: =IF(M13="","",IF(M13="READY","",TRIM(IF(A13="","missing entity_type; ","")&IF(B13="","missing entity_key; ","")&IF(C13="","missing contact_order; ","")&IF(D13="","missing contact_type; ","")&IF(E13="","missing number; ","")&IF(J13="","missing status; ","")&IF(AND(A13="client",COUNTIF(الزبائن!$A$6:$A$505,B13)=0),"client key not found; ","")&IF(AND(A13="proposed_name",COUNTIF('أسماء مقترحة'!$A$6:$A$505,B13)=0),"proposed_name key not found; ","")&IF(AND(D13="mobile",J13<>"invalid",NOT(OR(AND(LEN(E13&"")=10,LEFT(E13&"",2)="09"),AND(LEN(E13&"")=9,LEFT(E13&"",1)="9")))),"mobile must be 09XXXXXXXX or status invalid; ","")&IF(COUNTIFS($A$6:$A$505,A13,$B$6:$B$505,B13,$E$6:$E$505,E13)>1,"duplicate number for same entity; ",""))))
M14: =IF(AND(A14="",B14="",E14=""),"",IF(OR(A14="",B14="",C14="",D14="",E14="",J14="",AND(A14="client",COUNTIF(الزبائن!$A$6:$A$505,B14)=0),AND(A14="proposed_name",COUNTIF('أسماء مقترحة'!$A$6:$A$505,B14)=0),AND(D14="mobile",J14<>"invalid",NOT(OR(AND(LEN(E14&"")=10,LEFT(E14&"",2)="09"),AND(LEN(E14&"")=9,LEFT(E14&"",1)="9")))),COUNTIFS($A$6:$A$505,A14,$B$6:$B$505,B14,$E$6:$E$505,E14)>1),"REVIEW","READY")) | N14: =IF(M14="","",IF(M14="READY","",TRIM(IF(A14="","missing entity_type; ","")&IF(B14="","missing entity_key; ","")&IF(C14="","missing contact_order; ","")&IF(D14="","missing contact_type; ","")&IF(E14="","missing number; ","")&IF(J14="","missing status; ","")&IF(AND(A14="client",COUNTIF(الزبائن!$A$6:$A$505,B14)=0),"client key not found; ","")&IF(AND(A14="proposed_name",COUNTIF('أسماء مقترحة'!$A$6:$A$505,B14)=0),"proposed_name key not found; ","")&IF(AND(D14="mobile",J14<>"invalid",NOT(OR(AND(LEN(E14&"")=10,LEFT(E14&"",2)="09"),AND(LEN(E14&"")=9,LEFT(E14&"",1)="9")))),"mobile must be 09XXXXXXXX or status invalid; ","")&IF(COUNTIFS($A$6:$A$505,A14,$B$6:$B$505,B14,$E$6:$E$505,E14)>1,"duplicate number for same entity; ",""))))
M15: =IF(AND(A15="",B15="",E15=""),"",IF(OR(A15="",B15="",C15="",D15="",E15="",J15="",AND(A15="client",COUNTIF(الزبائن!$A$6:$A$505,B15)=0),AND(A15="proposed_name",COUNTIF('أسماء مقترحة'!$A$6:$A$505,B15)=0),AND(D15="mobile",J15<>"invalid",NOT(OR(AND(LEN(E15&"")=10,LEFT(E15&"",2)="09"),AND(LEN(E15&"")=9,LEFT(E15&"",1)="9")))),COUNTIFS($A$6:$A$505,A15,$B$6:$B$505,B15,$E$6:$E$505,E15)>1),"REVIEW","READY")) | N15: =IF(M15="","",IF(M15="READY","",TRIM(IF(A15="","missing entity_type; ","")&IF(B15="","missing entity_key; ","")&IF(C15="","missing contact_order; ","")&IF(D15="","missing contact_type; ","")&IF(E15="","missing number; ","")&IF(J15="","missing status; ","")&IF(AND(A15="client",COUNTIF(الزبائن!$A$6:$A$505,B15)=0),"client key not found; ","")&IF(AND(A15="proposed_name",COUNTIF('أسماء مقترحة'!$A$6:$A$505,B15)=0),"proposed_name key not found; ","")&IF(AND(D15="mobile",J15<>"invalid",NOT(OR(AND(LEN(E15&"")=10,LEFT(E15&"",2)="09"),AND(LEN(E15&"")=9,LEFT(E15&"",1)="9")))),"mobile must be 09XXXXXXXX or status invalid; ","")&IF(COUNTIFS($A$6:$A$505,A15,$B$6:$B$505,B15,$E$6:$E$505,E15)>1,"duplicate number for same entity; ",""))))
